<?xml version="1.0" encoding="UTF-8"?>
<!-- Generated by org.testng.reporters.JUnitReportReporter -->
<testsuite hostname="LAPTOP-D2A3ARO3" failures="0" tests="6" name="com.qa.test.testing" time="0.012" errors="5" timestamp="4 Apr 2022 21:14:01 GMT">
  <testcase classname="com.qa.test.testing" name="tone" time="0.000">
    <error message="expected [b] but found [a]" type="java.lang.AssertionError">
      <![CDATA[java.lang.AssertionError: expected [b] but found [a]
	at org.testng.Assert.fail(Assert.java:94)
	at org.testng.Assert.failNotEquals(Assert.java:494)
	at org.testng.Assert.assertEquals(Assert.java:123)
	at org.testng.Assert.assertEquals(Assert.java:176)
	at org.testng.Assert.assertEquals(Assert.java:186)
	at com.qa.test.testing.tone(testing.java:14)
	at java.base/jdk.internal.reflect.NativeMethodAccessorImpl.invoke0(Native Method)
	at java.base/jdk.internal.reflect.NativeMethodAccessorImpl.invoke(NativeMethodAccessorImpl.java:78)
	at java.base/jdk.internal.reflect.DelegatingMethodAccessorImpl.invoke(DelegatingMethodAccessorImpl.java:43)
	at java.base/java.lang.reflect.Method.invoke(Method.java:567)
	at org.testng.internal.MethodInvocationHelper.invokeMethod(MethodInvocationHelper.java:80)
	at org.testng.internal.Invoker.invokeMethod(Invoker.java:714)
	at org.testng.internal.Invoker.retryFailed(Invoker.java:1049)
	at org.testng.internal.Invoker.invokeTestMethods(Invoker.java:1254)
	at org.testng.internal.TestMethodWorker.invokeTestMethods(TestMethodWorker.java:127)
	at org.testng.internal.TestMethodWorker.run(TestMethodWorker.java:111)
	at org.testng.TestRunner.privateRun(TestRunner.java:767)
	at org.testng.TestRunner.run(TestRunner.java:617)
	at org.testng.SuiteRunner.runTest(SuiteRunner.java:334)
	at org.testng.SuiteRunner.runSequentially(SuiteRunner.java:329)
	at org.testng.SuiteRunner.privateRun(SuiteRunner.java:291)
	at org.testng.SuiteRunner.run(SuiteRunner.java:240)
	at org.testng.SuiteRunnerWorker.runSuite(SuiteRunnerWorker.java:52)
	at org.testng.SuiteRunnerWorker.run(SuiteRunnerWorker.java:86)
	at org.testng.TestNG.runSuitesSequentially(TestNG.java:1198)
	at org.testng.TestNG.runSuitesLocally(TestNG.java:1123)
	at org.testng.TestNG.run(TestNG.java:1031)
	at org.testng.remote.AbstractRemoteTestNG.run(AbstractRemoteTestNG.java:115)
	at org.testng.remote.RemoteTestNG.initAndRun(RemoteTestNG.java:251)
	at org.testng.remote.RemoteTestNG.main(RemoteTestNG.java:77)
]]>
    </error>
  </testcase> <!-- tone -->
  <testcase classname="com.qa.test.testing" name="ttwo" time="0.000"/>
  <testcase classname="com.qa.test.testing" name="tthree" time="0.001">
    <error message="expected [b] but found [a]" type="java.lang.AssertionError">
      <![CDATA[java.lang.AssertionError: expected [b] but found [a]
	at org.testng.Assert.fail(Assert.java:94)
	at org.testng.Assert.failNotEquals(Assert.java:494)
	at org.testng.Assert.assertEquals(Assert.java:123)
	at org.testng.Assert.assertEquals(Assert.java:176)
	at org.testng.Assert.assertEquals(Assert.java:186)
	at com.qa.test.testing.tthree(testing.java:29)
	at java.base/jdk.internal.reflect.NativeMethodAccessorImpl.invoke0(Native Method)
	at java.base/jdk.internal.reflect.NativeMethodAccessorImpl.invoke(NativeMethodAccessorImpl.java:78)
	at java.base/jdk.internal.reflect.DelegatingMethodAccessorImpl.invoke(DelegatingMethodAccessorImpl.java:43)
	at java.base/java.lang.reflect.Method.invoke(Method.java:567)
	at org.testng.internal.MethodInvocationHelper.invokeMethod(MethodInvocationHelper.java:80)
	at org.testng.internal.Invoker.invokeMethod(Invoker.java:714)
	at org.testng.internal.Invoker.invokeTestMethod(Invoker.java:901)
	at org.testng.internal.Invoker.invokeTestMethods(Invoker.java:1231)
	at org.testng.internal.TestMethodWorker.invokeTestMethods(TestMethodWorker.java:127)
	at org.testng.internal.TestMethodWorker.run(TestMethodWorker.java:111)
	at org.testng.TestRunner.privateRun(TestRunner.java:767)
	at org.testng.TestRunner.run(TestRunner.java:617)
	at org.testng.SuiteRunner.runTest(SuiteRunner.java:334)
	at org.testng.SuiteRunner.runSequentially(SuiteRunner.java:329)
	at org.testng.SuiteRunner.privateRun(SuiteRunner.java:291)
	at org.testng.SuiteRunner.run(SuiteRunner.java:240)
	at org.testng.SuiteRunnerWorker.runSuite(SuiteRunnerWorker.java:52)
	at org.testng.SuiteRunnerWorker.run(SuiteRunnerWorker.java:86)
	at org.testng.TestNG.runSuitesSequentially(TestNG.java:1198)
	at org.testng.TestNG.runSuitesLocally(TestNG.java:1123)
	at org.testng.TestNG.run(TestNG.java:1031)
	at org.testng.remote.AbstractRemoteTestNG.run(AbstractRemoteTestNG.java:115)
	at org.testng.remote.RemoteTestNG.initAndRun(RemoteTestNG.java:251)
	at org.testng.remote.RemoteTestNG.main(RemoteTestNG.java:77)
]]>
    </error>
  </testcase> <!-- tthree -->
  <testcase classname="com.qa.test.testing" name="tone" time="0.001">
    <error message="expected [b] but found [a]" type="java.lang.AssertionError">
      <![CDATA[java.lang.AssertionError: expected [b] but found [a]
	at org.testng.Assert.fail(Assert.java:94)
	at org.testng.Assert.failNotEquals(Assert.java:494)
	at org.testng.Assert.assertEquals(Assert.java:123)
	at org.testng.Assert.assertEquals(Assert.java:176)
	at org.testng.Assert.assertEquals(Assert.java:186)
	at com.qa.test.testing.tone(testing.java:14)
	at java.base/jdk.internal.reflect.NativeMethodAccessorImpl.invoke0(Native Method)
	at java.base/jdk.internal.reflect.NativeMethodAccessorImpl.invoke(NativeMethodAccessorImpl.java:78)
	at java.base/jdk.internal.reflect.DelegatingMethodAccessorImpl.invoke(DelegatingMethodAccessorImpl.java:43)
	at java.base/java.lang.reflect.Method.invoke(Method.java:567)
	at org.testng.internal.MethodInvocationHelper.invokeMethod(MethodInvocationHelper.java:80)
	at org.testng.internal.Invoker.invokeMethod(Invoker.java:714)
	at org.testng.internal.Invoker.retryFailed(Invoker.java:1049)
	at org.testng.internal.Invoker.invokeTestMethods(Invoker.java:1254)
	at org.testng.internal.TestMethodWorker.invokeTestMethods(TestMethodWorker.java:127)
	at org.testng.internal.TestMethodWorker.run(TestMethodWorker.java:111)
	at org.testng.TestRunner.privateRun(TestRunner.java:767)
	at org.testng.TestRunner.run(TestRunner.java:617)
	at org.testng.SuiteRunner.runTest(SuiteRunner.java:334)
	at org.testng.SuiteRunner.runSequentially(SuiteRunner.java:329)
	at org.testng.SuiteRunner.privateRun(SuiteRunner.java:291)
	at org.testng.SuiteRunner.run(SuiteRunner.java:240)
	at org.testng.SuiteRunnerWorker.runSuite(SuiteRunnerWorker.java:52)
	at org.testng.SuiteRunnerWorker.run(SuiteRunnerWorker.java:86)
	at org.testng.TestNG.runSuitesSequentially(TestNG.java:1198)
	at org.testng.TestNG.runSuitesLocally(TestNG.java:1123)
	at org.testng.TestNG.run(TestNG.java:1031)
	at org.testng.remote.AbstractRemoteTestNG.run(AbstractRemoteTestNG.java:115)
	at org.testng.remote.RemoteTestNG.initAndRun(RemoteTestNG.java:251)
	at org.testng.remote.RemoteTestNG.main(RemoteTestNG.java:77)
]]>
    </error>
  </testcase> <!-- tone -->
  <testcase classname="com.qa.test.testing" name="tone" time="0.008">
    <error message="expected [b] but found [a]" type="java.lang.AssertionError">
      <![CDATA[java.lang.AssertionError: expected [b] but found [a]
	at org.testng.Assert.fail(Assert.java:94)
	at org.testng.Assert.failNotEquals(Assert.java:494)
	at org.testng.Assert.assertEquals(Assert.java:123)
	at org.testng.Assert.assertEquals(Assert.java:176)
	at org.testng.Assert.assertEquals(Assert.java:186)
	at com.qa.test.testing.tone(testing.java:14)
	at java.base/jdk.internal.reflect.NativeMethodAccessorImpl.invoke0(Native Method)
	at java.base/jdk.internal.reflect.NativeMethodAccessorImpl.invoke(NativeMethodAccessorImpl.java:78)
	at java.base/jdk.internal.reflect.DelegatingMethodAccessorImpl.invoke(DelegatingMethodAccessorImpl.java:43)
	at java.base/java.lang.reflect.Method.invoke(Method.java:567)
	at org.testng.internal.MethodInvocationHelper.invokeMethod(MethodInvocationHelper.java:80)
	at org.testng.internal.Invoker.invokeMethod(Invoker.java:714)
	at org.testng.internal.Invoker.invokeTestMethod(Invoker.java:901)
	at org.testng.internal.Invoker.invokeTestMethods(Invoker.java:1231)
	at org.testng.internal.TestMethodWorker.invokeTestMethods(TestMethodWorker.java:127)
	at org.testng.internal.TestMethodWorker.run(TestMethodWorker.java:111)
	at org.testng.TestRunner.privateRun(TestRunner.java:767)
	at org.testng.TestRunner.run(TestRunner.java:617)
	at org.testng.SuiteRunner.runTest(SuiteRunner.java:334)
	at org.testng.SuiteRunner.runSequentially(SuiteRunner.java:329)
	at org.testng.SuiteRunner.privateRun(SuiteRunner.java:291)
	at org.testng.SuiteRunner.run(SuiteRunner.java:240)
	at org.testng.SuiteRunnerWorker.runSuite(SuiteRunnerWorker.java:52)
	at org.testng.SuiteRunnerWorker.run(SuiteRunnerWorker.java:86)
	at org.testng.TestNG.runSuitesSequentially(TestNG.java:1198)
	at org.testng.TestNG.runSuitesLocally(TestNG.java:1123)
	at org.testng.TestNG.run(TestNG.java:1031)
	at org.testng.remote.AbstractRemoteTestNG.run(AbstractRemoteTestNG.java:115)
	at org.testng.remote.RemoteTestNG.initAndRun(RemoteTestNG.java:251)
	at org.testng.remote.RemoteTestNG.main(RemoteTestNG.java:77)
]]>
    </error>
  </testcase> <!-- tone -->
  <testcase classname="com.qa.test.testing" name="tone" time="0.002">
    <error message="expected [b] but found [a]" type="java.lang.AssertionError">
      <![CDATA[java.lang.AssertionError: expected [b] but found [a]
	at org.testng.Assert.fail(Assert.java:94)
	at org.testng.Assert.failNotEquals(Assert.java:494)
	at org.testng.Assert.assertEquals(Assert.java:123)
	at org.testng.Assert.assertEquals(Assert.java:176)
	at org.testng.Assert.assertEquals(Assert.java:186)
	at com.qa.test.testing.tone(testing.java:14)
	at java.base/jdk.internal.reflect.NativeMethodAccessorImpl.invoke0(Native Method)
	at java.base/jdk.internal.reflect.NativeMethodAccessorImpl.invoke(NativeMethodAccessorImpl.java:78)
	at java.base/jdk.internal.reflect.DelegatingMethodAccessorImpl.invoke(DelegatingMethodAccessorImpl.java:43)
	at java.base/java.lang.reflect.Method.invoke(Method.java:567)
	at org.testng.internal.MethodInvocationHelper.invokeMethod(MethodInvocationHelper.java:80)
	at org.testng.internal.Invoker.invokeMethod(Invoker.java:714)
	at org.testng.internal.Invoker.retryFailed(Invoker.java:1049)
	at org.testng.internal.Invoker.invokeTestMethods(Invoker.java:1254)
	at org.testng.internal.TestMethodWorker.invokeTestMethods(TestMethodWorker.java:127)
	at org.testng.internal.TestMethodWorker.run(TestMethodWorker.java:111)
	at org.testng.TestRunner.privateRun(TestRunner.java:767)
	at org.testng.TestRunner.run(TestRunner.java:617)
	at org.testng.SuiteRunner.runTest(SuiteRunner.java:334)
	at org.testng.SuiteRunner.runSequentially(SuiteRunner.java:329)
	at org.testng.SuiteRunner.privateRun(SuiteRunner.java:291)
	at org.testng.SuiteRunner.run(SuiteRunner.java:240)
	at org.testng.SuiteRunnerWorker.runSuite(SuiteRunnerWorker.java:52)
	at org.testng.SuiteRunnerWorker.run(SuiteRunnerWorker.java:86)
	at org.testng.TestNG.runSuitesSequentially(TestNG.java:1198)
	at org.testng.TestNG.runSuitesLocally(TestNG.java:1123)
	at org.testng.TestNG.run(TestNG.java:1031)
	at org.testng.remote.AbstractRemoteTestNG.run(AbstractRemoteTestNG.java:115)
	at org.testng.remote.RemoteTestNG.initAndRun(RemoteTestNG.java:251)
	at org.testng.remote.RemoteTestNG.main(RemoteTestNG.java:77)
]]>
    </error>
  </testcase> <!-- tone -->
</testsuite> <!-- com.qa.test.testing -->
